Workbook

Sheet README
A1: Cost and Pricing Model
A2: Document 05 of the proposal package. Every number on the calculation sheets is a formula driven by the Assumptions sheet.
B4: HOW TO USE
B5: 1. Change only BLUE cells on the Assumptions and Rate_Card sheets. Black cells are formulas; green cells link to other sheets.
B6: 2. Yellow-filled cells are the key commercial levers to agree with the client: blended rate, support tier, and the deployment pattern per tier.
B7: 3. Run_Cost_by_Tier shows monthly operating cost for four tiers (pilot to group scale). Build_Effort shows role effort and fees per phase. Pricing_Options shows the three commercial structures. TCO_3yr adds them up.
B8: 4. Prices are 2026 list prices from public pricing pages (see Sources column and comments). They change; confirm before quoting.
B10: COLOUR LEGEND
B11: Blue text = input you may change. Black text = formula. Green text = link from another sheet. Yellow fill = key assumption to agree with the client.
B13: SHEETS
B14: Assumptions: volumes, prices, and unit costs. Rate_Card: roles and rates. Run_Cost_by_Tier: monthly run cost. Build_Effort: fees by phase. Pricing_Options: commercial structures. TCO_3yr: three-year view.
B16: IMPORTANT
B17: Run cost excludes build fees. Build fees exclude cloud and AI usage, which are passed through at cost from the client's own accounts. All figures in USD, excluding VAT.

Sheet Assumptions
A1: Assumptions and unit prices
A2: Blue = inputs. Tier columns: 0 Pilot, 1 Departmental, 2 Enterprise/Sovereign, 3 Group-scale.
A4: Volume driver | B4: Tier 0 Pilot | C4: Tier 1 Dept | D4: Tier 2 Enterprise | E4: Tier 3 Group | F4: Unit | G4: Notes / source
A5: Named users | B5: 10 | C5: 50 | D5: 300 | E5: 1500 | F5: users | G5: Client to confirm in discovery
A6: Documents in corpus (cumulative) | B6: 2000 | C6: 25000 | D6: 250000 | E6: 1500000 | F6: docs | G6: Indicative; pilot limit 5,000 in SOW
A7: Average pages per document | B7: 20 | C7: 20 | D7: 20 | E7: 20 | F7: pages | G7: Contracts and reports; spreadsheets counted by sheet
A8: Tokens per page | B8: 600 | C8: 600 | D8: 600 | E8: 600 | F8: tokens | G8: Roughly 450 words per page
A9: Share of pages that are scans needing OCR | B9: 0.3 | C9: 0.3 | D9: 0.3 | E9: 0.3 | F9: % | G9: GCC corpora often have many scanned Arabic pages
A10: New documents per month (share of corpus) | B10: 0.05 | C10: 0.05 | D10: 0.05 | E10: 0.05 | F10: % | G10: Ongoing ingestion after initial load
A11: Questions per user per working day | B11: 5 | C11: 5 | D11: 4 | E11: 3 | F11: questions | G11: Executives ask fewer, analysts more
A12: Working days per month | B12: 22 | C12: 22 | D12: 22 | E12: 22 | F12: days
A13: Input tokens per question (retrieved passages + prompt) | B13: 12000 | C13: 12000 | D13: 12000 | E13: 12000 | F13: tokens | G13: 8-12 passages of 400-600 tokens plus instructions
A14: Output tokens per question (answer + citations + grounding pass) | B14: 1500 | C14: 1500 | D14: 1500 | E14: 1500 | F14: tokens | G14: Includes the second grounding pass
A15: Share of questions answered by Opus 5 (rest Sonnet 5) | B15: 0.4 | C15: 0.4 | D15: 0.4 | E15: 0.4 | F15: % | G15: Complex questions and contradiction adjudication
A16: Extraction tokens per page (claims pass, Sonnet 5) | B16: 900 | C16: 900 | D16: 900 | E16: 900 | F16: tokens | G16: Input page tokens + structured output
A17: Prompt-cache and batch discount on ingestion | B17: 0.4 | C17: 0.4 | D17: 0.4 | E17: 0.4 | F17: % | G17: Batch API 50% off; caching on shared prefixes
A18: Outreach messages per month (CRM) | B18: 200 | C18: 1500 | D18: 8000 | E18: 40000 | F18: messages | G18: Email mostly; WhatsApp priced separately
A19: Share of AI-assisted drafts | B19: 0.5 | C19: 0.5 | D19: 0.5 | E19: 0.5 | F19: %
A20: Tokens per AI-assisted draft (in + out) | B20: 4000 | C20: 4000 | D20: 4000 | E20: 4000 | F20: tokens | G20: Sonnet 5
A21: Deployment pattern (A cloud, B hybrid, C sovereign) | B21: A | C21: B | D21: C | E21: C | F21: pattern | G21: Key lever: C adds GPU cost and removes most API cost
A22: Share of AI processing routed in-region under pattern B | B22: 0 | C22: 0.3 | D22: 1 | E22: 1 | F22: % | G22: Set to 1 for pattern C
A23: GPU nodes for in-region models (0 if pattern A) | B23: 0 | C23: 1 | D23: 4 | E23: 20 | F23: nodes | G23: Each node ~ 1x H100-class 80GB; two for HA at tier 2+
A25: Unit price (2026 list) | B25: Price | F25: Unit | G25: Source
A26: Claude Opus 5 input | B26: 5 | F26: USD / M tokens | G26: Anthropic pricing, 2026 (claude-opus-5)
A27: Claude Opus 5 output | B27: 25 | F27: USD / M tokens | G27: Anthropic pricing, 2026
A28: Claude Sonnet 5 input | B28: 2 | F28: USD / M tokens | G28: Anthropic pricing, 2026 (claude-sonnet-5)
A29: Claude Sonnet 5 output | B29: 10 | F29: USD / M tokens | G29: Anthropic pricing, 2026
A30: Voyage voyage-3.5 embeddings | B30: 0.02 | F30: USD / M tokens | G30: Voyage AI pricing page, 2026; first 200M tokens free
A31: Voyage rerank-2.5 | B31: 0.05 | F31: USD / M tokens | G31: Voyage AI pricing page, 2026; verify current rate
A32: OCR (Azure AI Document Intelligence, read/layout) | B32: 1.5 | F32: USD / 1,000 pages | G32: Azure pricing, UAE North; verify current rate
A33: Supabase Pro (pilot database, storage, auth) | B33: 25 | F33: USD / month | G33: supabase.com/pricing, 2026, plus usage
A34: Vercel Pro (pilot web hosting) | B34: 20 | F34: USD / seat / month | G34: vercel.com/pricing, 2026
A35: Managed PostgreSQL in GCC region, tier 1 | B35: 400 | F35: USD / month | G35: AWS RDS / Azure Database, mid-size instance with storage; estimate
A36: Managed PostgreSQL in GCC region, tier 2 (HA) | B36: 2500 | F36: USD / month | G36: Multi-AZ, larger instance, PITR; estimate
A37: Managed PostgreSQL in GCC region, tier 3 (HA, read replicas) | B37: 9000 | F37: USD / month | G37: Estimate
... A41: GPU node (H100-class 80GB) in-region, on-demand | B41: 4.5 | F41: USD / hour | G41: Hyperscaler GCC region on-demand; reserved pricing 30-50% lower; verify
A42: Hours per month | B42: 730 | F42: hours
A43: Observability, security tooling, backups, tier 1 | B43: 300 | F43: USD / month | G43: Langfuse cloud or self-host, Sentry, WAF; estimate
A44: Observability, security tooling, backups, tier 2 | B44: 2000 | F44: USD / month | G44: Plus SIEM export, KMS, pen-test amortised; estimate
A45: Observability, security tooling, backups, tier 3 | B45: 8000 | F45: USD / month | G45: Estimate
...

Sheet Rate_Card
A1: Rate card and blended rate
A2: Blue = inputs. Rates are indicative ranges by delivery location; set the yellow blended rate for the quote.
A4: Role | B4: Weekly rate (USD) | C4: Daily rate (USD) | D4: Hourly rate (USD) | E4: Guidance
A5: Engagement lead / solution architect | B5: 6000 | C5: =B5/5 -> 1200 | D5: =B5/40 -> 150 | E5: Senior; sets architecture and quality gate
A6: AI engineer (Python) | B6: 4500 | C6: =B6/5 -> 900 | D6: =B6/40 -> 112.5 | E6: Retrieval, extraction, evaluation
A7: Full-stack engineer (TypeScript) | B7: 4000 | C7: =B7/5 -> 800 | D7: =B7/40 -> 100 | E7: Web app, Core API, CRM workflow
A8: QA and evaluation analyst | B8: 2500 | C8: =B8/5 -> 500 | D8: =B8/40 -> 62.5 | E8: Golden set, tests, acceptance
A9: Project manager | B9: 3000 | C9: =B9/5 -> 600 | D9: =B9/40 -> 75 | E9: Plan, risks, client reporting
A10: UX designer | B10: 3000 | C10: =B10/5 -> 600 | D10: =B10/40 -> 75 | E10: Interface, Arabic layout
A11: Security and DevOps specialist | B11: 4500 | C11: =B11/5 -> 900 | D11: =B11/40 -> 112.5 | E11: IaC, hardening, pen-test coordination
A13: Blended weekly rate used for fees (set this) | B13: =AVERAGE(B5:B11) -> 3928.5714 | E13: Indicative market ranges per person-week (2026): South Asia 1,000-2,000; Eastern Europe 2,500-4,500; GCC-based / UK / US 5,000-9,000. Set rates to match your delivery model.
A14: Managed service: support tier as share of annual platform fee | B14: 0.2
A15: Managed service: annual platform fee as share of build fees (M0-M4) | B15: 0.18

Sheet Run_Cost_by_Tier
A1: Monthly run cost by tier (USD)
A2: All cells are formulas. Initial ingestion is a one-off shown separately; monthly figures include ongoing ingestion of new documents.
A4: Line | B4: Tier 0 Pilot | C4: Tier 1 Dept | D4: Tier 2 Enterprise | E4: Tier 3 Group | F4: How it is calculated
A5: Corpus pages | B5: =(Assumptions!B$6*Assumptions!B$7) -> 40000 | C5: =(Assumptions!C$6*Assumptions!C$7) -> 500000 | D5: =(Assumptions!D$6*Assumptions!D$7) -> 5000000 | E5: =(Assumptions!E$6*Assumptions!E$7) -> 30000000 | F5: documents x pages per document
A6: Questions per month | B6: =(Assumptions!B$5*Assumptions!B$11*Assumptions!B$12) -> 1100 | C6: =(Assumptions!C$5*Assumptions!C$11*Assumptions!C$12) -> 5500 | D6: =(Assumptions!D$5*Assumptions!D$11*Assumptions!D$12) -> 26400 | E6: =(Assumptions!E$5*Assumptions!E$11*Assumptions!E$12) -> 99000 | F6: users x questions per day x working days
A7: ONE-OFF: initial ingestion, embeddings | B7: =((Assumptions!B$6*Assumptions!B$7)*Assumptions!B$8)/1000000*Assumptions!$B$30 -> 0.48 | C7: =((Assumptions!C$6*Assumptions!C$7)*Assumptions!C$8)/1000000*Assumptions!$B$30 -> 6 | D7: =((Assumptions!D$6*Assumptions!D$7)*Assumptions!D$8)/1000000*Assumptions!$B$30 -> 60 | E7: =((Assumptions!E$6*Assumptions!E$7)*Assumptions!E$8)/1000000*Assumptions!$B$30 -> 360 | F7: corpus tokens x embedding price (first 200M tokens free, not netted)
A8: ONE-OFF: initial ingestion, OCR of scanned pages | B8: =(Assumptions!B$6*Assumptions!B$7)*Assumptions!B$9/1000*Assumptions!$B$32 -> 18 | C8: =(Assumptions!C$6*Assumptions!C$7)*Assumptions!C$9/1000*Assumptions!$B$32 -> 225 | D8: =(Assumptions!D$6*Assumptions!D$7)*Assumptions!D$9/1000*Assumptions!$B$32 -> 2250 | E8: =(Assumptions!E$6*Assumptions!E$7)*Assumptions!E$9/1000*Assumptions!$B$32 -> 13500 | F8: scanned pages x OCR price per 1,000
A9: ONE-OFF: initial ingestion, claims extraction (Sonnet 5, batch) | B9: =(Assumptions!B$6*Assumptions!B$7)*Assumptions!B$16/1000000*(Assumptions!$B$28*0.75+Assumptions!$B$29*0.25)*(1-Assumptions!B$17)*(1-Assumptions!B$22) -> 86.4 | C9: =(Assumptions!C$6*Assumptions!C$7)*Assumptions!C$16/1000000*(Assumptions!$B$28*0.75+Assumptions!$B$29*0.25)*(1-Assumptions!C$17)*(1-Assumptions!C$22) -> 756 | D9: =(Assumptions!D$6*Assumptions!D$7)*Assumptions!D$16/1000000*(Assumptions!$B$28*0.75+Assumptions!$B$29*0.25)*(1-Assumptions!D$17)*(1-Assumptions!D$22) -> 0 | E9: =(Assumptions!E$6*Assumptions!E$7)*Assumptions!E$16/1000000*(Assumptions!$B$28*0.75+Assumptions!$B$29*0.25)*(1-Assumptions!E$17)*(1-Assumptions!E$22) -> 0 | F9: pages x extraction tokens x blended Sonnet price x (1 - discount) x share via API
A10: ONE-OFF: initial ingestion total | B10: =SUM(B7:B9) -> 104.88 | C10: =SUM(C7:C9) -> 987 | D10: =SUM(D7:D9) -> 2310 | E10: =SUM(E7:E9) -> 13860
A11: Monthly: ongoing ingestion (share of corpus per month) | B11: =B10*Assumptions!B$10 -> 5.244 | C11: =C10*Assumptions!C$10 -> 49.35 | D11: =D10*Assumptions!D$10 -> 115.5 | E11: =E10*Assumptions!E$10 -> 693 | F11: one-off total x monthly new-document share
A12: Monthly: question answering, Opus 5 share | B12: =B6*Assumptions!B$15*(Assumptions!B$13*Assumptions!$B$26+Assumptions!B$14*Assumptions!$B$27)/1000000*(1-Assumptions!B$22) -> 42.9 | C12: =C6*Assumptions!C$15*(Assumptions!C$13*Assumptions!$B$26+Assumptions!C$14*Assumptions!$B$27)/1000000*(1-Assumptions!C$22) -> 150.15 | D12: =D6*Assumptions!D$15*(Assumptions!D$13*Assumptions!$B$26+Assumptions!D$14*Assumptions!$B$27)/1000000*(1-Assumptions!D$22) -> 0 | E12: =E6*Assumptions!E$15*(Assumptions!E$13*Assumptions!$B$26+Assumptions!E$14*Assumptions!$B$27)/1000000*(1-Assumptions!E$22) -> 0 | F12: questions x Opus share x (in tokens x price + out tokens x price)
A13: Monthly: question answering, Sonnet 5 share | B13: =B6*(1-Assumptions!B$15)*(Assumptions!B$13*Assumptions!$B$28+Assumptions!B$14*Assumptions!$B$29)/1000000*(1-Assumptions!B$22) -> 25.74 | C13: =C6*(1-Assumptions!C$15)*(Assumptions!C$13*Assumptions!$B$28+Assumptions!C$14*Assumptions!$B$29)/1000000*(1-Assumptions!C$22) -> 90.09 | D13: =D6*(1-Assumptions!D$15)*(Assumptions!D$13*Assumptions!$B$28+Assumptions!D$14*Assumptions!$B$29)/1000000*(1-Assumptions!D$22) -> 0 | E13: =E6*(1-Assumptions!E$15)*(Assumptions!E$13*Assumptions!$B$28+Assumptions!E$14*Assumptions!$B$29)/1000000*(1-Assumptions!E$22) -> 0 | F13: as above for Sonnet
A14: Monthly: re-ranking | B14: =B6*40*500/1000000*Assumptions!$B$31 -> 1.1 | C14: =C6*40*500/1000000*Assumptions!$B$31 -> 5.5 | D14: =D6*40*500/1000000*Assumptions!$B$31 -> 26.4 | E14: =E6*40*500/1000000*Assumptions!$B$31 -> 99 | F14: questions x 40 candidates x 500 tokens x rerank price
A15: Monthly: CRM AI-assisted drafts (Sonnet 5) | B15: =Assumptions!B$18*Assumptions!B$19*Assumptions!B$20/1000000*(Assumptions!$B$28*0.6+Assumptions!$B$29*0.4)*(1-Assumptions!B$22) -> 2.08 | C15: =Assumptions!C$18*Assumptions!C$19*Assumptions!C$20/1000000*(Assumptions!$B$28*0.6+Assumptions!$B$29*0.4)*(1-Assumptions!C$22) -> 10.92 | D15: =Assumptions!D$18*Assumptions!D$19*Assumptions!D$20/1000000*(Assumptions!$B$28*0.6+Assumptions!$B$29*0.4)*(1-Assumptions!D$22) -> 0 | E15: =Assumptions!E$18*Assumptions!E$19*Assumptions!E$20/1000000*(Assumptions!$B$28*0.6+Assumptions!$B$29*0.4)*(1-Assumptions!E$22) -> 0 | F15: messages x AI share x tokens x blended price
A16: Monthly: WhatsApp conversations | B16: =Assumptions!B$18*Assumptions!$B$48*Assumptions!$B$47 -> 0.6 | C16: =Assumptions!C$18*Assumptions!$B$48*Assumptions!$B$47 -> 4.5 | D16: =Assumptions!D$18*Assumptions!$B$48*Assumptions!$B$47 -> 24 | E16: =Assumptions!E$18*Assumptions!$B$48*Assumptions!$B$47 -> 120 | F16: messages x WhatsApp share x per-conversation price
A17: Monthly: AI and messaging subtotal | B17: =SUM(B11:B16) -> 77.664 | C17: =SUM(C11:C16) -> 310.51 | D17: =SUM(D11:D16) -> 165.9 | E17: =SUM(E11:E16) -> 912
A18: Monthly: database and storage | B18: =Assumptions!$B$33 -> 25 | C18: =Assumptions!$B$35 -> 400 | D18: =Assumptions!$B$36 -> 2500 | E18: =Assumptions!$B$37 -> 9000 | F18: Supabase Pro at pilot; managed PostgreSQL in region above
A19: Monthly: application hosting | B19: =Assumptions!$B$34*2+60 -> 100 | C19: =Assumptions!$B$38 -> 600 | D19: =Assumptions!$B$39 -> 4000 | E19: =Assumptions!$B$40 -> 18000 | F19: Vercel Pro (2 seats) + small container at pilot; containers in region above
A20: Monthly: in-region GPU nodes (patterns B/C) | B20: =Assumptions!B$23*Assumptions!$B$41*Assumptions!$B$42 -> 0 | C20: =Assumptions!C$23*Assumptions!$B$41*Assumptions!$B$42 -> 3285 | D20: =Assumptions!D$23*Assumptions!$B$41*Assumptions!$B$42 -> 13140 | E20: =Assumptions!E$23*Assumptions!$B$41*Assumptions!$B$42 -> 65700 | F20: nodes x hourly price x hours; reserved pricing can cut this 30-50%
A21: Monthly: observability, security tooling, backups | B21: =40 -> 40 | C21: =Assumptions!$B$43 -> 300 | D21: =Assumptions!$B$44 -> 2000 | E21: =Assumptions!$B$45 -> 8000 | F21: Sentry/Langfuse free tiers at pilot
A22: Monthly: infrastructure subtotal | B22: =SUM(B18:B21) -> 165 | C22: =SUM(C18:C21) -> 4585 | D22: =SUM(D18:D21) -> 21640 | E22: =SUM(E18:E21) -> 100700
A23: MONTHLY RUN COST TOTAL | B23: =B17+B22 -> 242.664 | C23: =C17+C22 -> 4895.51 | D23: =D17+D22 -> 21805.9 | E23: =E17+E22 -> 101612 | F23: AI and messaging + infrastructure
A24: Annual run cost | B24: =B23*12 -> 2911.968 | C24: =C23*12 -> 58746.12 | D24: =D23*12 -> 261670.8 | E24: =E23*12 -> 1219344
A25: Run cost per named user per month | B25: =IF(Assumptions!B$5=0,0,B23/Assumptions!B$5) -> 24.2664 | C25: =IF(Assumptions!C$5=0,0,C23/Assumptions!C$5) -> 97.9102 | D25: =IF(Assumptions!D$5=0,0,D23/Assumptions!D$5) -> 72.686333 | E25: =IF(Assumptions!E$5=0,0,E23/Assumptions!E$5) -> 67.741333 | F25: guards against zero users
A27: Note: one-off ingestion (row 10) is paid once at load and again only for re-indexing; it is excluded from the monthly total. Pilot totals sit within the USD 150-400 per month range quoted in the deck when the volume drivers are at the Tier 0 defaults.

Sheet Build_Effort
A1: Build effort and fees by phase
A2: Blue = person-weeks per role per phase (inputs). Fees = person-weeks x blended weekly rate from Rate_Card.
A4: Role | B4: Phase 0 Discovery | C4: Phase 1 Foundation | D4: Phase 2 Verification + approval | E4: Phase 3 Pilot | F4: Phase 4 Production | G4: Total weeks | H4: Fee (USD)
A5: Engagement lead / solution architect | B5: 1 | C5: 2.5 | D5: 2 | E5: 2.5 | F5: 2 | G5: =SUM(B5:F5) -> 10 | H5: =G5*Rate_Card!$B$13 -> 39285.714
A6: AI engineer (Python) | B6: 1 | C6: 5 | D6: 4 | E6: 6 | F6: 3 | G6: =SUM(B6:F6) -> 19 | H6: =G6*Rate_Card!$B$13 -> 74642.857
A7: Full-stack engineer (TypeScript) | B7: 0.5 | C7: 5 | D7: 4 | E7: 5 | F7: 3 | G7: =SUM(B7:F7) -> 17.5 | H7: =G7*Rate_Card!$B$13 -> 68750
A8: Second engineer (AI or full-stack) | B8: 0 | C8: 1 | D8: 4 | E8: 4 | F8: 3 | G8: =SUM(B8:F8) -> 12 | H8: =G8*Rate_Card!$B$13 -> 47142.857
A9: QA and evaluation analyst | B9: 0.5 | C9: 1.5 | D9: 2 | E9: 3 | F9: 2 | G9: =SUM(B9:F9) -> 9 | H9: =G9*Rate_Card!$B$13 -> 35357.143
A10: Project manager | B10: 0.6 | C10: 1.5 | D10: 1.2 | E10: 1.8 | F10: 1.5 | G10: =SUM(B10:F10) -> 6.6 | H10: =G10*Rate_Card!$B$13 -> 25928.571
A11: UX designer | B11: 0.4 | C11: 1.2 | D11: 0.6 | E11: 0.4 | F11: 0.2 | G11: =SUM(B11:F11) -> 2.8 | H11: =G11*Rate_Card!$B$13 -> 11000
A12: Security and DevOps specialist | B12: 0.4 | C12: 0.8 | D12: 0.6 | E12: 0.8 | F12: 2 | G12: =SUM(B12:F12) -> 4.6 | H12: =G12*Rate_Card!$B$13 -> 18071.429
A13: Total person-weeks | B13: =SUM(B5:B12) -> 4.4 | C13: =SUM(C5:C12) -> 18.5 | D13: =SUM(D5:D12) -> 18.4 | E13: =SUM(E5:E12) -> 23.5 | F13: =SUM(F5:F12) -> 16.7 | G13: =SUM(G5:G12) -> 81.5 | H13: =SUM(H5:H12) -> 320178.57
A14: Fee per phase (USD) | B14: =B13*Rate_Card!$B$13 -> 17285.714 | C14: =C13*Rate_Card!$B$13 -> 72678.571 | D14: =D13*Rate_Card!$B$13 -> 72285.714 | E14: =E13*Rate_Card!$B$13 -> 92321.429 | F14: =F13*Rate_Card!$B$13 -> 65607.143 | H14: =SUM(B14:F14) -> 320178.57
A15: Contingency on build (share) | B15: 0.1
A16: Total build fees including contingency (M0-M4) | H16: =H14*(1+B15) -> 352196.43
A18: Calendar duration by phase (weeks) | B18: 2 | C18: 5 | D18: 4 | E18: 6 | F18: 5 | G18: =SUM(B18:F18) -> 22 | H18: Phases overlap; elapsed timeline is 20 weeks
A19: Average team size (FTE) by phase | B19: =IF(B18=0,0,B13/B18) -> 2.2 | C19: =IF(C18=0,0,C13/C18) -> 3.7 | D19: =IF(D18=0,0,D13/D18) -> 4.6 | E19: =IF(E18=0,0,E13/E18) -> 3.9166667 | F19: =IF(F18=0,0,F13/F18) -> 3.34
A21: Milestone payment schedule (from Pricing structure in Document 14)
A22: Milestone | B22: Basis | H22: Amount (USD)
A23: M0 Discovery complete (week 2) | B23: 100% of Phase 0 | H23: =Build_Effort!$B$14*(1+Build_Effort!$B$15) -> 19014.286
A24: On signature of Phases 1-2 | B24: 40% of Phases 1-2 | H24: =0.4*(Build_Effort!$C$14*(1+Build_Effort!$B$15)+Build_Effort!$D$14*(1+Build_Effort!$B$15)) -> 63784.286
A25: M1 Working structure (week 6) | B25: 30% of Phases 1-2 | H25: =0.3*(Build_Effort!$C$14*(1+Build_Effort!$B$15)+Build_Effort!$D$14*(1+Build_Effort!$B$15)) -> 47838.214
A26: M2 Integrated demo (week 9) | B26: 30% of Phases 1-2 | H26: =0.3*(Build_Effort!$C$14*(1+Build_Effort!$B$15)+Build_Effort!$D$14*(1+Build_Effort!$B$15)) -> 47838.214
A27: M3 Pilot exit (week 15) | B27: 100% of Phase 3 | H27: =Build_Effort!$E$14*(1+Build_Effort!$B$15) -> 101553.57
A28: M4 Production go-live (week 20) | B28: 100% of Phase 4 | H28: =Build_Effort!$F$14*(1+Build_Effort!$B$15) -> 72167.857
A29: Total (equals build fees incl. contingency) | H29: =SUM(H23:H28) -> 352196.43
A30: Check: difference to build total (should be 0) | H30: =ROUND(H29-Build_Effort!$H$16,2) -> 0

Sheet Pricing_Options
A1: Commercial structures
A2: Three ways to contract the same scope. Figures link to Build_Effort, Rate_Card and Run_Cost_by_Tier.
A4: Option A: Fixed price by milestone (recommended) | B4: USD | E4: Notes
A5: Build fees, M0-M4, including contingency | B5: =Build_Effort!$H$16 -> 352196.43
A6: Annual managed service: platform fee | B6: =B5*Rate_Card!$B$15 -> 63395.357 | E6: Share of build fees per year; covers upgrades, model changes, evaluation re-runs, minor enhancements
A7: Annual managed service: support tier | B7: =B6*Rate_Card!$B$14 -> 12679.071 | E7: Standard 15%, Business 20%, Enterprise 30% of platform fee (set on Rate_Card)
A8: Annual managed service total (excluding pass-through cloud and AI) | B8: =B6+B7 -> 76074.429
A9: Pass-through run cost, year 1, at the selected tier (see TCO_3yr) | B9: =TCO_3yr!C8 -> 58746.12
A11: Option B: Time and materials with monthly cap | B11: USD | E11: Notes
A12: Blended weekly rate | B12: =Rate_Card!$B$13 -> 3928.5714
A13: Planned person-weeks (from Build_Effort) | B13: =Build_Effort!G13 -> 81.5
A14: Monthly cap (person-weeks x rate / months) | B14: =B12*B13/5 -> 64035.714 | E14: Assumes 20 weeks = 5 months; client pays actuals up to the cap
A15: Expected total at plan (no contingency needed) | B15: =B12*B13 -> 320178.57
A16: Suitable when scope is expected to evolve during the pilot; risk sits with the client, so the rate is typically 5-10% lower than fixed-price equivalents.
A18: Option C: Subscription (build amortised into an annual fee) | B18: USD | E18: Notes
A19: Contract term (years) | B19: 3
A20: Financing uplift on amortised build | B20: 0.12 | E20: Compensates for deferred payment and cancellation risk
A21: Annual subscription = build x (1+uplift) / term + managed service | B21: =B5*(1+B20)/B19+B8 -> 207561.1
A22: Lower entry cost for the client; total over the term is higher than Option A. Code ownership can still transfer at end of term or on early buy-out.
A24: Smaller starting scopes (fixed price) | B24: USD | E24: Notes
A25: Discovery only (Phase 0) | B25: =Build_Effort!$B$14*(1+Build_Effort!$B$15) -> 19014.286
A26: Discovery + System 1 working structure only | B26: =Build_Effort!$B$14*(1+Build_Effort!$B$15)+0.55*Build_Effort!$C$14*(1+Build_Effort!$B$15) -> 62984.821 | E26: Platform layer plus assistant; CRM deferred. 55% of Phase 1 effort.
A27: Discovery + CRM for one category only | B27: =Build_Effort!$B$14*(1+Build_Effort!$B$15)+0.5*Build_Effort!$C$14*(1+Build_Effort!$B$15) -> 58987.5 | E27: Platform layer plus CRM; assistant deferred. 50% of Phase 1 effort.
A28: Clickable prototype at week 4 (add-on to Phase 1) | B28: =1.5*Rate_Card!$B$13 -> 5892.8571 | E28: About 1.5 person-weeks of demo preparation

Sheet TCO_3yr
A1: Three-year total cost of ownership
A2: Choose the tier path in the blue cells. Build fees in year 1; managed service and run cost every year; optional Phase 5 scale-out budget.
A4: Item | B4: Tier in year | C4: Year 1 | D4: Year 2 | E4: Year 3 | F4: Notes
A5: Tier operated in each year (0-3) | C5: 1 | D5: 2 | E5: 2 | F5: Typical path: pilot then departmental in year 1, enterprise from year 2
A6: Build fees (M0-M4) | C6: =Build_Effort!$H$16 -> 352196.43 | D6: 0 | E6: 0
A7: Managed service (platform fee + support) | C7: =Pricing_Options!B8*0.5 -> 38037.214 | D7: =Pricing_Options!B8 -> 76074.429 | E7: =Pricing_Options!B8 -> 76074.429 | F7: Half year in year 1 (go-live at week 20)
A8: Run cost (pass-through cloud and AI) at the year's tier | C8: =INDEX(Run_Cost_by_Tier!$B$24:$E$24,1,C5+1) -> 58746.12 | D8: =INDEX(Run_Cost_by_Tier!$B$24:$E$24,1,D5+1) -> 261670.8 | E8: =INDEX(Run_Cost_by_Tier!$B$24:$E$24,1,E5+1) -> 261670.8 | F8: INDEX into annual run cost by tier
A9: One-off initial ingestion at the year's tier (re-index on tier change) | C9: =INDEX(Run_Cost_by_Tier!$B$10:$E$10,1,C5+1) -> 987 | D9: =IF(D5<>C5,INDEX(Run_Cost_by_Tier!$B$10:$E$10,1,D5+1),0) -> 2310 | E9: =IF(E5<>D5,INDEX(Run_Cost_by_Tier!$B$10:$E$10,1,E5+1),0) -> 0
A10: Phase 5 scale-out budget (connectors, sovereign switch, integrations) | C10: 0 | D10: =8*Rate_Card!$B$13 -> 31428.571 | E10: =6*Rate_Card!$B$13 -> 23571.429 | F10: Person-weeks x blended rate; adjust to roadmap
A11: TOTAL PER YEAR | C11: =SUM(C6:C10) -> 449966.76 | D11: =SUM(D6:D10) -> 371483.8 | E11: =SUM(E6:E10) -> 361316.66
A12: THREE-YEAR TOTAL | C12: =SUM(C11:E11) -> 1182767.2
A14: Reading the result: the client sees a single build investment in year 1, a predictable managed-service fee, and run costs that scale with the tier they choose. Build fees do not recur when moving up a tier; only run cost and, if chosen, Phase 5 work change.
